<?xml version="1.0"?>
<robot>


       <!--////////////////////////// links ////////////////////////////////////////////////-->

  <!-- Hokuyo Laser -->
  
  
  <link name="hokuyo_link">
    <collision>
      <origin xyz="0 0 0" rpy="0 0 0"/>
      <geometry>
    <box size="0.1 0.1 0.1"/>
      </geometry>
    </collision>

    <visual>
      <origin xyz="0 0 0" rpy="0 0 0"/>
      <geometry>
        <mesh filename="package://gecko_description/meshes/hokuyo.dae"/>
      </geometry>
    </visual>

    <inertial>
      <mass value="1" />
      <origin xyz="0 0 0" rpy="0 0 0"/>
      <inertia ixx="1" ixy="0" ixz="0" iyy="1" iyz="0" izz="1" />
    </inertial>
  </link>
  
   <joint name="hokuyo_joint" type="prismatic">
    <axis xyz="0 1 0" />
    <origin xyz="0 0 0" rpy="0 1.3 ${-pi/2}"/>
    <parent link="horizontal_traslation_link"/>
    <child link="hokuyo_link"/>
    <limit effort="10.0" lower="-0.2" upper="0.2" velocity="0.5"/>
  </joint>
  
  
  <link name="horizontal_traslation_link">
  
      <visual>
      <origin xyz="0 0 0" rpy="0 0 0"/>
	<geometry>
    <box size="0.01 0.01 0.01"/>
      </geometry>
    </visual>
    
    <collision>
      <origin xyz="0 0 0" rpy="0 0 0"/>
      <geometry>
    <box size="0 0 0"/>
      </geometry>
    </collision>


    <inertial>
      <mass value="0.5" />
      <origin xyz="0 0 0" rpy="0 0 0"/>
                <inertia ixx="1.0" ixy="0.0" ixz="0.0"
                     iyy="1.0" iyz="0.0"
                     izz="1.0" />

    </inertial>
  </link>
  
   <joint name="horizontal_traslation_link_joint" type="prismatic">
    <axis xyz="0 1 0" />
    <origin xyz="0 0.4 0.2" rpy="0 0 0"/>
    <parent link="base_link"/>
    <child link="horizontal_traslation_link"/>
    <limit effort="1000" lower="-0.66" upper="0.08" velocity="0.5"/>
  </joint>
  
  
  
   <!-- hokuyo -->
  <gazebo reference="hokuyo_link">
    <sensor type="ray" name="head_hokuyo_sensor">
      <pose>0 0 0 0 0 0</pose>
      <visualize>true</visualize>
      <update_rate>40</update_rate>
      <ray>
        <scan>
          <horizontal>
            <samples>720</samples>
            <resolution>1</resolution>
            <min_angle>-1</min_angle>
            <max_angle>1</max_angle>
          </horizontal>
        </scan>
        <range>
          <min>0.10</min>
          <max>30.0</max>
          <resolution>0.01</resolution>
        </range>
        <noise>
          <type>gaussian</type>

          <mean>0.0</mean>
          <stddev>0.01</stddev>
        </noise>
      </ray>
      <plugin name="gazebo_ros_head_hokuyo_controller" filename="libgazebo_ros_laser.so">
        <topicName>/hokuyo_scan</topicName>
        <frameName>hokuyo_link</frameName>
      </plugin>
    </sensor>
  </gazebo>

</robot>
